Workbook

Sheet boq- 271225
S4: Birthday | T4: 31st Jan
A6: Date : | B6: 45991 | E6: Project Code :
A7: Client Name : | B7: Rahul Dhanawat | E7: Quotation Revision : | F7: 0
A8: Address : | B8: 10BKC | E8: Elemantra Contact Person : | F8: Payal- 93724 07848
A10: Quotation Summary | F10: SR.NO | G10: Description | H10: Amount
B11: Area in Sqft | D11: 1673 | F11: 1 | G11: Loose furniture | H11: =K249 -> 460000
A12: SR.NO | B12: Description | D12: Amount | F12: 2 | G12: Additional items | H12: =L266 -> 2875600
A13: 1 | B13: Civil | D13: =N46 -> 1126050 | F13: 3 | G13: Additional items -2 | H13: =N276 -> 244500
A14: 2 | B14: Plumbing | D14: =N52 -> 180000 | G14: Total B | H14: =SUM(H11:H13) -> 3580100
A15: 3 | B15: Electrical | D15: =N55 -> 585550 | F15: Total A+B | H15: =D21+H11+H12+H13 -> 13807554
A16: 4 | B16: POP | D16: =N62 -> 442500 | F16: GST 18% extra
A17: 5 | B17: Carpentry | D17: =N163 -> 6224875
A18: 6 | B18: Painting | D18: =N169 -> 978478.5
A19: 7 | B19: Miscellenious | D19: =K174 -> 190000
A20: 8 | B20: Design Consultation Fees(10%) | D20: 500000
B21: Total A | D21: =SUM(D13:D20) -> 10227454
B22: Per Sqft Rate | D22: =(D21/D11) -> 6113.2418
A24: Sr.No | B24: Id | C24: Item Name | D24: Category | E24: Item Details | F24: Description | G24: UOM | H24: Elemantra Rates | J24: Quantity 14.03.2025 | K24: Amount | L24: Area | M24: Difference Amount | N24: Amount | O24: RA - 1 - WORK % | P24: RA - 1 - WORK %- AMOUNT | Q24: Location | R24: Remark | S24: MAHESH LOOSE ITEMS | T24: DEEPAK MODULAR | U24: ON SITE CARPENTRY | V24: CNC MEHTA
A25: Civil
A26: 1 | C26: Demolition | D26: walls | E26: NA | F26: Demolition | G26: sq.ft | H26: 250 | J26: =H26-(H26*16.622%) -> 208.445 | K26: 40 | L26: =3+3+7*9+100 -> 169 | M26: Entire kitchen this includes below platform as well since wwe are changing verticles it will get damage . | N26: =L26*H26 -> 42250 | O26: 1 | P26: =O26*N26 -> 42250 | Q26: servent ,samar & master bathroom door shifting | R26: keeping 100 sq.ft extra
A27: 2 | C27: civil | D27: walls | E27: NA | F27: Making | G27: sq.ft | H27: 350 | J27: - | K27: - | L27: =6*9 -> 54 | M27: Kitchen Window &door frame | N27: =L27*H27 -> 18900 | O27: 1 | P27: =O27*N27 -> 18900 | Q27: samar & master bathroom wall sfifting
A28: 3 | C28: civil | D28: kitchen platform | E28: NA | F28: includes marble verticals, base marble, moulding , cutting etc , also includes floor bedding with marble | G28: sq.ft | H28: 3000 | L28: 25 | N28: =L28*H28 -> 75000 | O28: 1 | P28: =O28*N28 -> 75000 | Q28: kitchen platform
A29: 4 | C29: civil | D29: utility platform | E29: NA | F29: includes marble verticals, base marble, moulding , cutting etc , also includes floor bedding with marble | G29: sq.ft | H29: 3000 | L29: 9 | N29: =L29*H29 -> 27000 | O29: 1 | P29: =O29*N29 -> 27000 | Q29: utility platform
A30: 5 | C30: civil | D30: Bathroom Tile | E30: 4x2 tile | F30: Laying of Wall tiles of approved colour and size as per drawing, over 20 mm thick cement mortar 1 : 4 ( 1 cement : 4 coarse sand ) and jointed with white cement slurry admixed with matching pigment to match the shade of tile & Grouting and spacer to be included. | G30: sq.ft | H30: 150 | L30: 936 | N30: =L30*H30 -> 140400 | O30: 1 | P30: =O30*N30 -> 140400 | Q30: 4 Bathroom Tile
A31: 6 | C31: civil | D31: Plaster | F31: Providing and laying 12-25 mm thick cement plaster of mis 1 : 4 (1 cement : 4 sand with 50% coarse sand & 50% fine sand) to all type of RCC / brick surface in line, level and plumb including providing wiremesh at all junctions of walls and ceilings etc. complete. | G31: sq.ft | H31: 125 | L31: 936 | N31: =L31*H31 -> 117000 | O31: 1 | P31: =O31*N31 -> 117000 | Q31: 4 Bathroom Tile
A32: 7 | C32: civil | D32: bathroom window frame | E32: single patti | F32: Granite Frame – up to 6 Inches width {Including Bevelling+ Cutting+ Polishing}. Excludes Granite cost | G32: sq.ft | H32: 450 | L32: =10*4+18+18+12+50 -> 138 | N32: =L32*H32 -> 62100 | O32: 1 | P32: =O32*N32 -> 62100 | Q32: 4 bathroom window and 1 kitchen window and 1 show unit window
A33: 8 | C33: civil | D33: brickbat | F33: =VLOOKUP($B33,'Rate card'!$A$4:$G285,5,FALSE) -> 0 | G33: sq.ft | H33: 200 | L33: =40*4 -> 160 | N33: =L33*H33 -> 32000 | O33: 1 | P33: =O33*N33 -> 32000 | Q33: 4 bathroom floor
A34: 9 | C34: civil | D34: waterproffing | E34: 2 cote | G34: sq.ft | H34: 250 | L34: =L33 -> 160 | N34: =L34*H34 -> 40000 | O34: 1 | P34: =O34*N34 -> 40000 | Q34: 4 bathroom floor
A35: 10 | C35: civil | D35: Bathroom floor tile | F35: Laying of Wall tiles of approved colour and size as per drawing, over 20 mm thick cement mortar 1 : 4 ( 1 cement : 4 coarse sand ) and jointed with white cement slurry admixed with matching pigment to match the shade of tile & Grouting and spacer to be included. | G35: sq.ft | H35: 150 | L35: =L34 -> 160 | N35: =L35*H35 -> 24000 | O35: 1 | P35: =O35*N35 -> 24000 | Q35: 4 bathroom floor
A36: 11 | C36: civil | D36: vanity counter | G36: ls | H36: 8000 | L36: 4 | N36: =L36*H36 -> 32000 | P36: =O36*N36 -> 0
A37: 12 | C37: civil | D37: ledge | G37: la | H37: 5000 | L37: 4 | N37: =L37*H37 -> 20000 | O37: 1 | P37: =O37*N37 -> 20000
A38: 13 | N38: =L38*H38 -> 0 | P38: =O38*N38 -> 0
A39: 14 | C39: civil | D39: plain tile | G39: sq.ft | H39: 120 | L39: 350 | N39: =L39*H39 -> 42000 | O39: 1 | P39: =O39*N39 -> 42000 | Q39: tile behid utility and below platform
A40: 15 | C40: civil | D40: marble wardrobe in utility area | G40: sq.ft | H40: 950 | L40: =12*8.5 -> 102 | N40: =L40*H40 -> 96900 | P40: =O40*N40 -> 0 | Q40: marble wardrobe in utility area | R40: shutters are not included
A41: 16 | C41: civil | G41: sq.ft | H41: 300 | L41: 150 | N41: =L41*H41 -> 45000 | O41: 1 | P41: =O41*N41 -> 45000
A42: 17 | C42: civil | D42: Marble Polish | G42: Sq.ft | H42: 85 | L42: 2500 | N42: =L42*H42 -> 212500 | P42: =O42*N42 -> 0
A43: 18 | C43: civil | D43: Niche | H43: 5000 | L43: 5 | N43: =L43*H43 -> 25000 | O43: 1 | P43: =O43*N43 -> 25000
A44: 19 | C44: civil | D44: Ledge | G44: Rft | H44: 2000 | L44: 15 | N44: =L44*H44 -> 30000 | O44: 1 | P44: =O44*N44 -> 30000
A45: 20 | C45: civil | D45: Bathroom dooe frame | G45: rft | H45: 550 | L45: =20*4 -> 80 | N45: =L45*H45 -> 44000 | P45: =O45*N45 -> 0 | R45: ?
L46: Total | N46: =SUM(N26:N45) -> 1126050 | P46: =SUM(P26:P45) -> 740650 | Q46: =P46/N46 -> 0.65774166
...

Sheet WO- Awdesh
A6: Date : | B6: 46029 | E6: Project Code : | F6: Wing 15 - 702
A7: Client Name : | B7: Rahul Dhanawat | E7: WO-1 | F7: AWDESH
A8: Address : | B8: 10BKC | E8: Elemantra Contact Person :
A9: Sr.No | B9: Id | C9: Item Name | D9: Category | E9: Item Details | F9: Description | G9: UOM | H9: Elemantra Rates | I9: awdesh rates | J9: Amount awdesh | K9: Area | L9: Amount | M9: Location | N9: Remarks
A10: Painting | K10: TOTAL
A11: 1 | B11: P 19 | C11: =VLOOKUP($B11,'Rate card'!$A$4:$G1006,2,FALSE) -> Paint | D11: =VLOOKUP($B11,'Rate card'!$A$4:$G1006,3,FALSE) -> Royal Shyne | E11: =VLOOKUP($B11,'Rate card'!$A$4:$G1006,4,FALSE) -> 2 Primer + 1 Putty + 2 RLE | F11: =VLOOKUP($B11,'Rate card'!$A$4:$G1006,5,FALSE) -> Painting with royal Shyne on ceiling, to give an even shade – Two or more coats on new work including preparation of surface. (_putty+_primer+_paint) as per requirement | G11: =VLOOKUP($B11,'Rate card'!$A$4:$G1006,6,FALSE) -> Sqft | H11: =VLOOKUP($B11,'Rate card'!$A$4:$J1006,8,FALSE) -> 42 | I11: 38 | J11: =I11*K11 -> 63574 | K11: 1673 | L11: =K11*H11 -> 70266 | M11: Ceiling
A12: =A11+1 -> 2 | B12: P 5 | C12: =VLOOKUP($B12,'Rate card'!$A$4:$G1006,2,FALSE) -> Paint | D12: =VLOOKUP($B12,'Rate card'!$A$4:$G1006,3,FALSE) -> Royal Shyne | E12: =VLOOKUP($B12,'Rate card'!$A$4:$G1006,4,FALSE) -> 2 Primer + 1 Putty + 2 RLE | F12: =VLOOKUP($B12,'Rate card'!$A$4:$G1006,5,FALSE) -> Painting with royal Shyne on walls, to give an even shade – Two or more coats on new work including preparation of surface. (_putty+_primer+_paint) as per requirement | G12: =VLOOKUP($B12,'Rate card'!$A$4:$G1006,6,FALSE) -> Sqft | H12: =VLOOKUP($B12,'Rate card'!$A$4:$J1006,8,FALSE) -> 45 | I12: 38 | J12: =I12*K12 -> 158935 | K12: =1673*2.5 -> 4182.5 | L12: =K12*H12 -> 188212.5 | M12: Walls
A13: =A12+1 -> 3 | B13: P 5 | C13: =VLOOKUP($B13,'Rate card'!$A$4:$G1006,2,FALSE) -> Paint | D13: Texture paint | E13: =VLOOKUP($B13,'Rate card'!$A$4:$G1006,4,FALSE) -> 2 Primer + 1 Putty + 2 RLE | F13: =VLOOKUP($B13,'Rate card'!$A$4:$G1006,5,FALSE) -> Painting with royal Shyne on walls, to give an even shade – Two or more coats on new work including preparation of surface. (_putty+_primer+_paint) as per requirement | G13: LS | H13: 25000 | I13: 15000 | J13: =I13*K13 -> 15000 | K13: 1 | L13: =K13*H13 -> 25000 | M13: Walls
A14: =A13+1 -> 4 | B14: P 5 | C14: =VLOOKUP($B14,'Rate card'!$A$4:$G1006,2,FALSE) -> Paint | D14: =VLOOKUP($B14,'Rate card'!$A$4:$G1006,3,FALSE) -> Royal Shyne | E14: =VLOOKUP($B14,'Rate card'!$A$4:$G1006,4,FALSE) -> 2 Primer + 1 Putty + 2 RLE | F14: =VLOOKUP($B14,'Rate card'!$A$4:$G1006,5,FALSE) -> Painting with royal Shyne on walls, to give an even shade – Two or more coats on new work including preparation of surface. (_putty+_primer+_paint) as per requirement | G14: =VLOOKUP($B14,'Rate card'!$A$4:$G1006,6,FALSE) -> Sqft | I14: 19 | L14: =K14*H14 -> 0 | M14: Dhaar
A15: 4 | C15: PU | D15: PU- ICA ROYAL ASIAN | G15: Sqft | H15: 350 | I15: 250 | J15: =I15*K15 -> 325000 | K15: 1300 | L15: =K15*H15 -> 455000 | M15: all areas
A16: 5 | C16: PU | D16: PU- ICA ROYAL ASIAN | E16: Dhaar | G16: Sqft | I16: 125
A17: 6 | B17: P 12 | C17: =VLOOKUP($B17,'Rate card'!$A$4:$G1006,2,FALSE) -> Polish | D17: =VLOOKUP($B17,'Rate card'!$A$4:$G1006,3,FALSE) -> Melamine | E17: =VLOOKUP($B17,'Rate card'!$A$4:$G1006,4,FALSE) | F17: As per specifications | G17: =VLOOKUP($B17,'Rate card'!$A$4:$G1006,6,FALSE) -> Sqft | H17: 120 | I17: 75 | J17: =I17*K17 -> 150000 | K17: 2000 | L17: =K17*H17 -> 240000 | M17: Veneer applications
J18: =sum(J11:J17) -> 712509 | K18: TOTAL | L18: =SUM(L11:L17) -> 978478.5

Sheet CNC ORDERS
A4: Carpentry | L4: QTY | M4: VENDOR RATES-Mehta CNC | N4: OUR RATES | O4: artist amount | P4: ply panelling rate | Q4: panelling amt | U4: VENDOR AMOUNT
A5: Living Room/Dining
A6: 1 | B6: CP 6 | C6: Carpentry | D6: Panelling with framing | E6: CNC MDF + Veneer | F6: Mr Ply+ply framing+Finish Veneer + Onyx | G6: =VLOOKUP($B6,'Rate card'!$A$4:$G1002,6,FALSE) -> Sqft | H6: 1500 | J6: 50 | K6: =H6*J6 -> 75000 | L6: 50 | M6: 35300 | N6: =L6*H6 -> 75000 | O6: 30000 | P6: 300 | Q6: =P6*L6 -> 15000 | S6: Wall Panel on sofa wall | T6: incluing master bedroom door and 3d panel | U6: =M6*L6 -> 1765000
A7: Master bed room
A8: 4 | B8: CP 3 | C8: =VLOOKUP($B8,'Rate card'!$A$4:$G1002,2,FALSE) -> Carpentry | D8: =VLOOKUP($B8,'Rate card'!$A$4:$G1002,3,FALSE) -> Panelling with framing | E8: stone finish | F8: =VLOOKUP($B8,'Rate card'!$A$4:$G1002,5,FALSE) -> MR ply + ply framing + 5mm clear mirror | G8: =VLOOKUP($B8,'Rate card'!$A$4:$G1002,6,FALSE) -> Sqft | H8: 1500 | J8: 50 | K8: =H8*J8 -> 75000 | L8: =12*9 -> 108 | M8: 34000 | N8: =L8*H8 -> 162000 | P8: 250 | Q8: =P8*L8 -> 27000 | S8: Bed back wall | U8: =M8*L8 -> 3672000
A9: Ranbeer's Bedroom
A10: 1 | B10: CP 1 | C10: Carpentry | D10: Panelling with framing | E10: =VLOOKUP($B10,'Rate card'!$A$4:$G1002,4,FALSE) -> Laminate Finish | F10: MR ply + ply framing + finish laminate | G10: =VLOOKUP($B10,'Rate card'!$A$4:$G1002,6,FALSE) -> Sqft | H10: 1500 | J10: 90 | K10: =H10*J10 -> 135000 | L10: =9*9 -> 81 | M10: 38500 | N10: =L10*H10 -> 121500 | P10: 300 | Q10: =P10*L10 -> 24300 | S10: Wall panel | U10: =M10*L10 -> 3118500
A11: Samars bedroom
A12: 1 | B12: CP 1 | C12: Carpentry | D12: Panelling with framing | E12: CNC Finish | G12: =VLOOKUP($B12,'Rate card'!$A$4:$G1002,6,FALSE) -> Sqft | H12: 1500 | L12: 95 | M12: 38050 | N12: =L12*H12 -> 142500 | P12: 400 | Q12: =P12*L12 -> 38000
M13: =SUM(M6:M12) -> 145850 | N13: =SUM(N6:N12) -> 501000 | O13: =SUM(O6:O10) -> 30000 | Q13: =SUM(Q6:Q12) -> 104300
U14: 119000
M16: =N13 -> 501000 | N16: our rate
M17: =O13 -> 30000 | N17: less artist amt
M18: =Q13 -> 104300 | N18: less ply panelling amt
M19: =M13 -> 145850 | N19: les cnc vendor amt
M20: =SUM(M17:M19) -> 280150 | N20: OUR MARGIN 42%
M21: =M16-M20 -> 220850

Sheet Sheet17
A1: Task | B1: Column 2 | C1: Dur | D1: Start date | E1: End date | F1: Milestone | G1: Timeline milestone | H1: Design remarks | I1: Execution remarks | J1: Wk 2 | K1: Wk 3 | L1: Wk 4 | M1: Wk 5 | N1: Wk 6 | O1: Wk 7 | P1: Wk 8 | Q1: Wk 9 | R1: Wk 10 | S1: Wk 11 | T1: Wk 12 | U1: Wk 13 | V1: Wk 14 | W1: Wk 15 | X1: Wk 16 | Y1: Wk 17 | Z1: Wk 18 | AA1: Wk 19 | AB1: Wk 20 | AC1: Wk 21 | AD1: Wk 22 | AE1: Wk 23 | AF1: Wk 24 | AG1: Wk 25 | AH1: Wk 26 | AI1: Wk 27
A2: Civil & plumbing | B2: In progress | C2: =E2-D2 -> 32 | D2: 45992 | E2: =E5 -> 46024 | F2: Civil completed (90%) | G2: Month 1 | J2: =E51-D2 -> 100
A3: Demolition & making of structure | B3: Completed | C3: 25 | D3: =D2 -> 45992 | E3: =D3+C3 -> 46017 | F3: Civil - 10%
A4: Plumbing + waterproofing | B4: Completed | C4: 15 | D4: =D2+5 -> 45997 | E4: =D4+C4 -> 46012 | F4: Civil - 25% | J4: Start date
A5: Kitchen and utility counter | B5: Completed | C5: 12 | D5: =E4 -> 46012 | E5: =D5+C5 -> 46024 | F5: Civil 65% | J5: =D2 -> 45992
A6: Bathrooms tiling | B6: In progress | D6: =E5 -> 46024 | E6: =D6+C6 -> 46024 | J6: =D3 -> 45992
A7: Living italian cladding | B7: Not started | D7: =E6 -> 46024 | E7: =D7+C7 -> 46024 | J7: =D4 -> 45997
A8: Living onyx cladiing | B8: Not started | D8: =E7 -> 46024 | E8: =D8+C8 -> 46024 | J8: =D5 -> 46012
A9: HVAC | B9: In progress | C9: =E9-D9 -> 79 | D9: =D10 -> 45999 | E9: =E11 -> 46078 | G9: Month 1 | J9: End date
A10: Piping | B10: Completed | C10: 18 | D10: =D3+7 -> 45999 | E10: =D10+C10 -> 46017 | F10: HVAC 30% | J10: =E51 -> 46092
A11: Machines installation | B11: Not started | C11: 20 | D11: 46058 | E11: =D11+C11 -> 46078 | F11: HVAC 100%
A12: Carpentry - Phase 1 | B12: In progress | C12: =E12-D12 -> 38 | D12: =D13 -> 46007 | E12: =E17 -> 46045 | F12: Carpentry on site (70%) | G12: Month 1 & 2
A13: Wall Panelling Living - framing | B13: In progress | C13: 8 | D13: =E3-10 -> 46007 | E13: =D13+C13 -> 46015 | F13: Carpentry on site (15%) | H13: Reduce wall panneling | I13: Parallel teams
A14: Wall Panelling bedrooms framing | B14: In progress | C14: 8 | D14: =E13 -> 46015 | E14: =D14+C14 -> 46023 | F14: Carpentry on site (25%) | H14: Reduce wall panneling | I14: Parallel teams
A15: Wall panelling - Ply+veneer+mirror | B15: In progress | C15: 12 | D15: =E14 -> 46023 | E15: =D15+C15 -> 46035 | F15: Carpentry on site (45%) | H15: Reduce wall panneling | I15: Parallel teams
A16: Carcass - making | B16: In progress | C16: 15 | D16: =D14+5 -> 46020 | E16: =D16+C16 -> 46035 | F16: Carpentry on site (60%)
A17: Lamintes/ veneer pasting | B17: In progress | C17: 15 | D17: =E16-5 -> 46030 | E17: =D17+C17 -> 46045 | F17: Carpentry on site (70%)
A18: Electricals - phase 1 | B18: In progress | C18: =E21-D19 -> 25 | D18: =D19 -> 45998 | E18: =D18+C18 -> 46023 | F18: Electrical completed (70%) | G18: Month 1
A19: Jari work | B19: Completed | C19: 10 | D19: =D2+6 -> 45998 | E19: =D19+C19 -> 46008 | F19: Electrical (15%) | I19: In house team
A20: Conduiting | B20: Completed | C20: 10 | D20: =E19 -> 46008 | E20: =D20+C20 -> 46018 | F20: Electrical (40%) | I20: In house team
A21: Wiring | B21: Completed | C21: 10 | D21: =E20-5 -> 46013 | E21: =D21+C21 -> 46023 | F21: Electrical (70%) | H21: Parallel electric | I21: In house team
A22: False ceiling & POP | B22: In progress | C22: =E22-D22 -> 64 | D22: =D23 -> 45998 | E22: =E27 -> 46062 | F22: False ceiling completed (95%) | G22: Month 1 & 2
A23: POP | B23: In progress | C23: 8 | D23: =D19 -> 45998 | E23: =D23+C23 -> 46006 | F23: False ceiling (15%) | H23: More MP
A24: Framing | B24: Completed | C24: 12 | D24: =E20-5 -> 46013 | E24: =D24+C24 -> 46025 | F24: False ceiling (35%) | H24: More MP
A25: bathrooms framing | B25: Not started | D25: =E20-10 -> 46008 | E25: =D25+C25 -> 46008
A26: Board closing | B26: Completed | C26: 12 | D26: =E21-10 -> 46013 | E26: =D26+C26 -> 46025 | F26: False ceiling (75%)
A27: Finishing | B27: Completed | C27: 25 | D27: =D33 -> 46037 | E27: =D27+C27 -> 46062 | F27: False ceiling (95%)
A28: Carpentry - modular | B28: In progress | C28: =E28-D28 -> 37 | D28: =D29 -> 46015 | E28: =E33 -> 46052 | F28: Modular installation (95%) | G28: Month 1 & 2
A29: Order placing wardrobes | B29: Order Placed | C29: 12 | D29: =E26-10 -> 46015 | E29: =D29+C29 -> 46027 | F29: Modular (30%) | H29: Place orders basis false ceiling framing | I29: Vendor to be finalized in month 1
A30: order placing loose items | B30: Order Placed | D30: =E27-10 -> 46052 | E30: =D30+C30 -> 46052
A31: Order delivery | B31: In progress | C31: 30 | D31: =E29-10 -> 46017 | E31: =D31+C31 -> 46047 | F31: Modular (80%)
A32: order placing kitchen | B32: Order Placed | D32: =E30-10 -> 46042 | E32: =D32+C32 -> 46042
A33: Installation | B33: Not started | C33: 15 | D33: =E31-10 -> 46037 | E33: =D33+C33 -> 46052 | F33: Modular (95%)
A34: Finishing phase | B34: In progress | C34: =E34-D34 -> 33 | D34: =D35 -> 46037 | E34: =E38 -> 46070 | F34: Finishing completed (95%) | G34: Month 2
A35: Laminate finishing | B35: In progress | C35: 15 | D35: =D33 -> 46037 | E35: =D35+C35 -> 46052 | I35: Mix of teams : In house & external
A36: Grooves, T patti, mirrors | B36: Not started | C36: 15 | D36: =E44 -> 46062 | E36: =D36+C36 -> 46077
A37: Veneer finishing | B37: In progress | D37: =D35 -> 46037 | E37: =D37+C37 -> 46037
A38: Civil finishing | B38: In progress | C38: 8 | D38: =D36 -> 46062 | E38: =D38+C38 -> 46070
A39: Electricals - phase 2 | B39: Not started | C39: =E39-D39 -> 35 | D39: =D40 -> 46052 | E39: =E41 -> 46087 | F39: Electricals (95%) | G39: Month 2
A40: Light fixing | B40: Not started | C40: 10 | D40: =E35 -> 46052 | E40: =D40+C40 -> 46062
...

Sheet loose items alisha  mahesh
A4: Sr.No | B4: Id | C4: Item Name | D4: Category | E4: Item Details | F4: Description | G4: UOM | H4: Elemantra Rates | J4: Quantity 14.03.2025 | K4: Amount | L4: Rate vendor | M4: Area | N4: Difference Amount | O4: Amount | P4: amount vendor | Q4: Location | R4: Remark
A5: Carpentry
A6: Living Room/Dining
A7: 1 | C7: Carpentry | D7: Dining Console | E7: MDF Finish | G7: Sqft | K7: 3000 | L7: 1950 | M7: 15 | N7: =M7*L7 -> 29250 | O7: =M7*K7 -> 45000 | P7: =L7*M7 -> 29250 | S7: 15000
A8: Mother's Bedroom | N8: =M8*L8 -> 0
A9: 1 | B9: CP 46 | C9: =VLOOKUP($B9,'Rate card'!$A$4:$G1003,2,FALSE) -> Carpentry | D9: Bed side table | E9: =VLOOKUP($B9,'Rate card'!$A$4:$G1003,4,FALSE) -> Laminate Finish | F9: =VLOOKUP($B9,'Rate card'!$A$4:$G1003,5,FALSE) -> MR ply + Inside laminate + finish laminate (1 Drawer) | G9: =VLOOKUP($B9,'Rate card'!$A$4:$G1003,6,FALSE) -> Nos | H9: 20000 | J9: 2 | K9: =H9*J9 -> 40000 | L9: 13000 | M9: 2 | N9: =M9*L9 -> 26000 | O9: =M9*H9 -> 40000 | P9: =M9*L9 -> 26000 | Q9: Bed side table | S9: 16000
A10: Samar's Bedroom | N10: =M10*L10 -> 0
A11: 1 | B11: CP 46 | C11: =VLOOKUP($B11,'Rate card'!$A$4:$G1003,2,FALSE) -> Carpentry | D11: Bed side table | E11: =VLOOKUP($B11,'Rate card'!$A$4:$G1003,4,FALSE) -> Laminate Finish | F11: =VLOOKUP($B11,'Rate card'!$A$4:$G1003,5,FALSE) -> MR ply + Inside laminate + finish laminate (1 Drawer) | G11: =VLOOKUP($B11,'Rate card'!$A$4:$G1003,6,FALSE) -> Nos | H11: 20000 | J11: 1 | K11: =H11*J11 -> 20000 | L11: 13000 | M11: 2 | N11: =M11*L11 -> 26000 | O11: =M11*H11 -> 40000 | P11: =M11*L11 -> 26000 | Q11: Bed side table | S11: 22000
A12: 2 | B12: CP 49 | C12: =VLOOKUP($B12,'Rate card'!$A$4:$G1003,2,FALSE) -> Carpentry | D12: =VLOOKUP($B12,'Rate card'!$A$4:$G1003,3,FALSE) -> Study Table | E12: =VLOOKUP($B12,'Rate card'!$A$4:$G1003,4,FALSE) -> Laminate Finish | F12: =VLOOKUP($B12,'Rate card'!$A$4:$G1003,5,FALSE) -> MR ply + Inside laminate + finish laminate (2 pencil drawers) | G12: =VLOOKUP($B12,'Rate card'!$A$4:$G1003,6,FALSE) -> Rft | H12: 4500 | J12: 4 | K12: =H12*J12 -> 18000 | L12: 2925 | M12: 4.5 | N12: =M12*L12 -> 13162.5 | P12: =M12*L12 -> 13162.5 | Q12: Study table
A13: Ranbeer's Bedroom | N13: =M13*L13 -> 0
A14: 1 | B14: CP 46 | C14: =VLOOKUP($B14,'Rate card'!$A$4:$G1003,2,FALSE) -> Carpentry | D14: Bed side table | E14: =VLOOKUP($B14,'Rate card'!$A$4:$G1003,4,FALSE) -> Laminate Finish | F14: =VLOOKUP($B14,'Rate card'!$A$4:$G1003,5,FALSE) -> MR ply + Inside laminate + finish laminate (1 Drawer) | G14: =VLOOKUP($B14,'Rate card'!$A$4:$G1003,6,FALSE) -> Nos | H14: 20000 | J14: 2 | K14: =H14*J14 -> 40000 | L14: 13000 | M14: 2 | N14: =M14*L14 -> 26000 | O14: =M14*H14 -> 40000 | P14: =M14*L14 -> 26000 | Q14: Bed side table | S14: 22000
A15: 2 | B15: CP 49 | C15: =VLOOKUP($B15,'Rate card'!$A$4:$G1003,2,FALSE) -> Carpentry | D15: =VLOOKUP($B15,'Rate card'!$A$4:$G1003,3,FALSE) -> Study Table | E15: =VLOOKUP($B15,'Rate card'!$A$4:$G1003,4,FALSE) -> Laminate Finish | F15: =VLOOKUP($B15,'Rate card'!$A$4:$G1003,5,FALSE) -> MR ply + Inside laminate + finish laminate (2 pencil drawers) | G15: =VLOOKUP($B15,'Rate card'!$A$4:$G1003,6,FALSE) -> Rft | H15: 4500 | J15: 4 | K15: =H15*J15 -> 18000 | L15: 2925 | M15: 5 | N15: =M15*L15 -> 14625 | O15: =M15*H15 -> 22500 | P15: =M15*L15 -> 14625 | Q15: Study table | S15: 30000
A16: Master bed room | N16: =M16*L16 -> 0 | O16: =M16*H16 -> 0
A17: 3 | B17: CP 46 | C17: Carpentry | D17: Bed side table | E17: Laminate Finish | F17: MR ply + Inside laminate + finish laminate (1 Drawer) | G17: Nos | H17: 20000 | J17: 2 | K17: =H17*J17 -> 40000 | M17: 2 | N17: =L17*H17 -> 0 | O17: =M17*H17 -> 40000 | P17: =O17*N17 -> 0 | Q17: Bed side table | S17: 22000
A18: 1 | B18: CP 25 | C18: =VLOOKUP($B18,'Rate card'!$A$4:$G1003,2,FALSE) -> Carpentry | D18: TV unit | E18: MDF Finish | F18: =VLOOKUP($B18,'Rate card'!$A$4:$G1003,5,FALSE) -> MR ply + Inside laminate + finish laminate | G18: R ft | H18: 4500 | J18: 7.25 | K18: =H18*J18 -> 32625 | L18: 2925 | M18: 9 | N18: =M18*L18 -> 26325 | O18: =M18*H18 -> 40500 | P18: =M18*L18 -> 26325 | Q18: TV unit | S18: 25000
A19: Master Toilet | N19: =M19*L19 -> 0 | O19: =M19*H19 -> 0
A20: 1 | B20: CP 25 | C20: =VLOOKUP($B20,'Rate card'!$A$4:$G1003,2,FALSE) -> Carpentry | D20: =VLOOKUP($B20,'Rate card'!$A$4:$G1003,3,FALSE) -> Carcass Storage | E20: =VLOOKUP($B20,'Rate card'!$A$4:$G1003,4,FALSE) -> Laminate Finish | F20: =VLOOKUP($B20,'Rate card'!$A$4:$G1003,5,FALSE) -> MR ply + Inside laminate + finish laminate | G20: =VLOOKUP($B20,'Rate card'!$A$4:$G1003,6,FALSE) -> Sqft | H20: =VLOOKUP($B20,'Rate card'!$A$4:$J1003,8,FALSE) -> 1800 | J20: 10 | K20: =H20*J20 -> 18000 | L20: 1170 | M20: 10 | N20: =M20*L20 -> 11700 | P20: =M20*L20 -> 11700 | Q20: vanity
A21: Mother's Toilet | N21: =M21*L21 -> 0
A22: 1 | B22: CP 25 | C22: =VLOOKUP($B22,'Rate card'!$A$4:$G1003,2,FALSE) -> Carpentry | D22: =VLOOKUP($B22,'Rate card'!$A$4:$G1003,3,FALSE) -> Carcass Storage | E22: =VLOOKUP($B22,'Rate card'!$A$4:$G1003,4,FALSE) -> Laminate Finish | F22: =VLOOKUP($B22,'Rate card'!$A$4:$G1003,5,FALSE) -> MR ply + Inside laminate + finish laminate | G22: =VLOOKUP($B22,'Rate card'!$A$4:$G1003,6,FALSE) -> Sqft | H22: =VLOOKUP($B22,'Rate card'!$A$4:$J1003,8,FALSE) -> 1800 | J22: 6 | K22: =H22*J22 -> 10800 | L22: 1170 | M22: 6 | N22: =M22*L22 -> 7020 | P22: =M22*L22 -> 7020 | Q22: vanity
A23: 2 | B23: CP 25 | C23: =VLOOKUP($B23,'Rate card'!$A$4:$G1003,2,FALSE) -> Carpentry | D23: =VLOOKUP($B23,'Rate card'!$A$4:$G1003,3,FALSE) -> Carcass Storage | E23: =VLOOKUP($B23,'Rate card'!$A$4:$G1003,4,FALSE) -> Laminate Finish | F23: =VLOOKUP($B23,'Rate card'!$A$4:$G1003,5,FALSE) -> MR ply + Inside laminate + finish laminate | G23: =VLOOKUP($B23,'Rate card'!$A$4:$G1003,6,FALSE) -> Sqft | H23: 1800 | J23: 15 | K23: =J23*H23 -> 27000 | L23: 1170 | M23: 15 | N23: =M23*L23 -> 17550 | O23: =M23*H23 -> 27000 | P23: =M23*L23 -> 17550 | Q23: vanity above storage | S23: 10000
A24: Samar's Toilet | N24: =M24*L24 -> 0 | O24: =M24*H24 -> 0
A25: 1 | B25: CP 25 | C25: =VLOOKUP($B25,'Rate card'!$A$4:$G1003,2,FALSE) -> Carpentry | D25: =VLOOKUP($B25,'Rate card'!$A$4:$G1003,3,FALSE) -> Carcass Storage | E25: =VLOOKUP($B25,'Rate card'!$A$4:$G1003,4,FALSE) -> Laminate Finish | F25: =VLOOKUP($B25,'Rate card'!$A$4:$G1003,5,FALSE) -> MR ply + Inside laminate + finish laminate | G25: =VLOOKUP($B25,'Rate card'!$A$4:$G1003,6,FALSE) -> Sqft | H25: =VLOOKUP($B25,'Rate card'!$A$4:$J1003,8,FALSE) -> 1800 | J25: 6 | K25: =H25*J25 -> 10800 | L25: 1170 | M25: 6 | N25: =M25*L25 -> 7020 | P25: =M25*L25 -> 7020 | Q25: vanity
A26: 2 | B26: CP 25 | C26: =VLOOKUP($B26,'Rate card'!$A$4:$G1003,2,FALSE) -> Carpentry | D26: =VLOOKUP($B26,'Rate card'!$A$4:$G1003,3,FALSE) -> Carcass Storage | E26: =VLOOKUP($B26,'Rate card'!$A$4:$G1003,4,FALSE) -> Laminate Finish | F26: =VLOOKUP($B26,'Rate card'!$A$4:$G1003,5,FALSE) -> MR ply + Inside laminate + finish laminate | G26: =VLOOKUP($B26,'Rate card'!$A$4:$G1003,6,FALSE) -> Sqft | H26: 1800 | J26: 15 | K26: =J26*H26 -> 27000 | L26: 1170 | M26: 15 | N26: =M26*L26 -> 17550 | O26: =M26*H26 -> 27000 | P26: =M26*L26 -> 17550 | Q26: vanity above storage | S26: 10000
A27: Ranbeer's Toilet | N27: =M27*L27 -> 0
A28: 1 | B28: CP 25 | C28: =VLOOKUP($B28,'Rate card'!$A$4:$G1003,2,FALSE) -> Carpentry | D28: =VLOOKUP($B28,'Rate card'!$A$4:$G1003,3,FALSE) -> Carcass Storage | E28: =VLOOKUP($B28,'Rate card'!$A$4:$G1003,4,FALSE) -> Laminate Finish | F28: =VLOOKUP($B28,'Rate card'!$A$4:$G1003,5,FALSE) -> MR ply + Inside laminate + finish laminate | G28: =VLOOKUP($B28,'Rate card'!$A$4:$G1003,6,FALSE) -> Sqft | H28: =VLOOKUP($B28,'Rate card'!$A$4:$J1003,8,FALSE) -> 1800 | J28: 6 | K28: =H28*J28 -> 10800 | L28: 1170 | M28: 6 | N28: =M28*L28 -> 7020 | P28: =M28*L28 -> 7020 | Q28: vanity
K29: =SUM(K7:K28) -> 316025 | N29: =SUM(N7:N28) -> 229222.5
O30: =SUM(O6:O28) -> 322000 | P30: =SUM(P6:P28) -> 229222.5 | S30: =SUM(S7:S29) -> 172000 | U30: =O30/1.25 -> 257600

Sheet R1
A6: Date : | B6: 45722 | E6: Project Code :
A7: Client Name : | B7: Rahul Dhanawat | E7: Quotation Revision : | F7: 0
A8: Address : | B8: 10BKC | E8: Elemantra Contact Person : | F8: Payal- 93724 07848
A10: Quotation Summary | G10: SR.NO | H10: Description | I10: Amount
B11: Area in Sqft | D11: 1673 | G11: 1 | H11: Loose furniture | I11: =J206 -> 415000
A12: SR.NO | B12: Description | D12: Amount | G12: 2 | H12: Additional items | I12: =J221 -> 2044935
A13: 1 | B13: Civil | D13: =J39 -> 979240 | H13: Total B | I13: =SUM(I11:I12) -> 2459935
A14: 2 | B14: Plumbing | D14: =J43 -> 245000 | G14: Total A+B | I14: =D21+I13 -> 9696162.8
A15: 3 | B15: Electrical | D15: =J46 -> 585550 | G15: GST 18% extra
A16: 4 | B16: POP | D16: =J54 -> 547340
A17: 5 | B17: Carpentry | D17: =J146 -> 3569150
A18: 6 | B18: Painting | D18: =J151 -> 308478.5
A19: 7 | B19: Miscellenious | D19: =J156 -> 120000
A20: 8 | B20: Design Consultation Fees(10%) | D20: =(SUM(D12:D19)+I13)*0.1 -> 881469.35
B21: Total A | D21: =SUM(D13:D20) -> 7236227.8
B22: Per Sqft Rate | D22: =(D21/D11) -> 4325.3006
A24: Sr.No | B24: Id | C24: Item Name | D24: Category | E24: Item Details | F24: Description | G24: UOM | H24: Elemantra Rates | I24: Quantity | J24: Amount | K24: Location | N24: Vendor Rate | O24: Amount
A25: Civil
A26: 1 | B26: D2 | C26: =VLOOKUP($B26,'Rate card'!$A$4:$G236,2,FALSE) -> Demolition | D26: =VLOOKUP($B26,'Rate card'!$A$4:$G236,3,FALSE) -> Brickwall - 6" | E26: =VLOOKUP($B26,'Rate card'!$A$4:$G236,4,FALSE) -> NA | F26: =VLOOKUP($B26,'Rate card'!$A$4:$G236,5,FALSE) -> Demolition | G26: =VLOOKUP($B26,'Rate card'!$A$4:$G236,6,FALSE) -> Sqft | H26: 500 | I26: =36+21 -> 57 | J26: =I26*H26 -> 28500 | K26: Kitchen & common toilet | L26: 22 | O26: =VLOOKUP($B26,'Rate card'!$A$4:$J236,7,FALSE) -> 20
A27: 2 | C27: Civil | D27: Brickwall - 4" | F27: Providing and laying 4" (100 MM) brick partition wall with good quality bricks well burnt 1st class in cement mortar 1:4 (1 cement : 4 coarse sand) including providing 2 nos of 6mm dia MS round bars at every IV course including scaffolding, curing, raking out joints etc. complete. | G27: =G26 -> Sqft | H27: 150 | I27: 24 | J27: =I27*H27 -> 3600 | L27: 160
A28: 3 | C28: Civil | D28: Kitchen wall tiles | E28: Upto( 4' x 2' ) tiles laying | F28: Laying of Wall tiles of approved colour and size as per drawing, over 20 mm thick cement mortar 1 : 4 ( 1 cement : 4 coarse sand ) and jointed with white cement slurry admixed with matching pigment to match the shade of tile & Grouting and spacer to be included. | G28: Sqft | H28: 140 | I28: 184 | J28: =I28*H28 -> 25760 | K28: Common toilet wall | L28: 120
A29: 4 | C29: Civil | D29: Bathroom wall tiles | E29: Upto( 4' x 2' ) tiles laying | F29: Laying of Wall tiles of approved colour and size as per drawing, over 20 mm thick cement mortar 1 : 4 ( 1 cement : 4 coarse sand ) and jointed with white cement slurry admixed with matching pigment to match the shade of tile & Grouting and spacer to be included. | G29: Sqft | H29: 140 | I29: 1930 | J29: =I29*H29 -> 270200 | K29: Toilets | L29: 120
A30: 5 | B30: C23 | C30: =VLOOKUP($B30,'Rate card'!$A$4:$G236,2,FALSE) -> Civil | D30: =VLOOKUP($B30,'Rate card'!$A$4:$G236,3,FALSE) -> Kitchen platform | E30: =VLOOKUP($B30,'Rate card'!$A$4:$G236,4,FALSE) -> Fully Modular Kitchen - Granite/Marble | F30: =VLOOKUP($B30,'Rate card'!$A$4:$G236,5,FALSE) -> Laying marble (18mm thk) of approved colour, shade and size on the platform as per drawing / flooring pattern, matching of grain, laid on a levelled, neat cement base with adhesive of approved make (laticrete) grouted of matching colour pigment to match the shade of stone and protection of floor to be taken into account.(cement concrete base taken into account in the civil works ) | G30: =VLOOKUP($B30,'Rate card'!$A$4:$G236,6,FALSE) -> Sqft | H30: 500 | I30: 36 | J30: =I30*H30 -> 18000 | K30: Kitchen | O30: =VLOOKUP($B30,'Rate card'!$A$4:$J236,7,FALSE) -> 150
A31: 6 | B31: C23 | C31: =VLOOKUP($B31,'Rate card'!$A$4:$G236,2,FALSE) -> Civil | D31: Utility platfrom | E31: =VLOOKUP($B31,'Rate card'!$A$4:$G236,4,FALSE) -> Fully Modular Kitchen - Granite/Marble | F31: =VLOOKUP($B31,'Rate card'!$A$4:$G236,5,FALSE) -> Laying marble (18mm thk) of approved colour, shade and size on the platform as per drawing / flooring pattern, matching of grain, laid on a levelled, neat cement base with adhesive of approved make (laticrete) grouted of matching colour pigment to match the shade of stone and protection of floor to be taken into account.(cement concrete base taken into account in the civil works ) | G31: =VLOOKUP($B31,'Rate card'!$A$4:$G236,6,FALSE) -> Sqft | H31: 500 | I31: 10 | J31: =I31*H31 -> 5000 | K31: utility | O31: =VLOOKUP($B31,'Rate card'!$A$4:$J236,7,FALSE) -> 150
A32: 7 | C32: Civil | D32: Floor Tiles | F32: Laying of floor tiles of approved colour and size as per drawing, over 20 mm thick cement mortar 1 : 4 ( 1 cement : 4 coarse sand ) and jointed with white cement slurry admixed with matching pigment to match the shade of tile & Grouting and spacer to be included. | G32: Sqft | H32: 140 | I32: 1673 | J32: =H32*I32 -> 234220 | K32: All areas
A33: 8 | B33: C14 | C33: =VLOOKUP($B33,'Rate card'!$A$4:$G236,2,FALSE) -> Civil | D33: =VLOOKUP($B33,'Rate card'!$A$4:$G236,3,FALSE) -> Floor PCC | E33: =VLOOKUP($B33,'Rate card'!$A$4:$G236,4,FALSE) | F33: =VLOOKUP($B33,'Rate card'!$A$4:$G236,5,FALSE) -> P / L 50-75mm average thickness Plain Cement Concrete 1:2:4 (1 cement : 2 coarse sand : 4 aggregate, 20mm and down gauge) , tamped, spaded, trowelled and smooth finish. | G33: =VLOOKUP($B33,'Rate card'!$A$4:$G236,6,FALSE) -> Sqft | H33: =VLOOKUP($B33,'Rate card'!$A$4:$J236,8,FALSE) -> 120 | I33: 1673 | J33: =H33*I33 -> 200760 | K33: All areas | N33: =VLOOKUP($B33,'Rate card'!$A$4:$J236,7,FALSE) -> 75 | O33: =I33*N33 -> 125475
A34: 9 | B34: C13 | C34: =VLOOKUP($B34,'Rate card'!$A$4:$G236,2,FALSE) -> Civil | D34: Wall Skirting | E34: =VLOOKUP($B34,'Rate card'!$A$4:$G236,4,FALSE) | F34: Laying of floor tiles of approved colour and size as per drawing, over 20 mm thick cement mortar 1 : 4 ( 1 cement : 4 coarse sand ) and jointed with white cement slurry admixed with matching pigment to match the shade of tile & Grouting and spacer to be included. | G34: =VLOOKUP($B34,'Rate card'!$A$4:$G236,6,FALSE) -> Rft | H34: 140 | I34: 450 | J34: =H34*I34 -> 63000 | K34: All areas | N34: =VLOOKUP($B34,'Rate card'!$A$4:$J236,7,FALSE) -> 40 | O34: =I34*N34 -> 18000
A35: 10 | B35: C15 | C35: =VLOOKUP($B35,'Rate card'!$A$4:$G236,2,FALSE) -> Civil | D35: =VLOOKUP($B35,'Rate card'!$A$4:$G236,3,FALSE) -> Granite frames | E35: =VLOOKUP($B35,'Rate card'!$A$4:$G236,4,FALSE) -> Single patti | F35: =VLOOKUP($B35,'Rate card'!$A$4:$G236,5,FALSE) -> Granite Frame – up to 6 Inches width {Including Bevelling+ Cutting+ Polishing}. Excludes Granite cost | G35: =VLOOKUP($B35,'Rate card'!$A$4:$G236,6,FALSE) -> Rft | H35: =VLOOKUP($B35,'Rate card'!$A$4:$J236,8,FALSE) -> 130 | I35: 150 | J35: =H35*I35 -> 19500 | K35: Living ,kitchen bed rooms & Toilets | N35: =VLOOKUP($B35,'Rate card'!$A$4:$J236,7,FALSE) -> 80 | O35: =I35*N35 -> 12000
A36: 11 | B36: C27 | C36: =VLOOKUP($B36,'Rate card'!$A$4:$G236,2,FALSE) -> Civil | D36: =VLOOKUP($B36,'Rate card'!$A$4:$G236,3,FALSE) -> Brickbat | E36: =VLOOKUP($B36,'Rate card'!$A$4:$G236,4,FALSE) | F36: =VLOOKUP($B36,'Rate card'!$A$4:$G236,5,FALSE) -> Providing & laying brickbat coba (6") with PCC | G36: =VLOOKUP($B36,'Rate card'!$A$4:$G236,6,FALSE) -> Sqft | H36: =VLOOKUP($B36,'Rate card'!$A$4:$J236,8,FALSE) -> 200 | I36: 226 | J36: =H36*I36 -> 45200 | K36: toilets | N36: =VLOOKUP($B36,'Rate card'!$A$4:$J236,7,FALSE) -> 150 | O36: =I36*N36 -> 33900
A37: 12 | B37: C30 | C37: =VLOOKUP($B37,'Rate card'!$A$4:$G236,2,FALSE) -> Civil | D37: =VLOOKUP($B37,'Rate card'!$A$4:$G236,3,FALSE) -> Waterproofing | E37: Floor & walls | F37: =VLOOKUP($B37,'Rate card'!$A$4:$G236,5,FALSE) -> Waterproofing with 2 coats | G37: =VLOOKUP($B37,'Rate card'!$A$4:$G236,6,FALSE) -> Sqft | H37: =VLOOKUP($B37,'Rate card'!$A$4:$J236,8,FALSE) -> 80 | I37: 350 | J37: =H37*I37 -> 28000 | K37: toilets | N37: =VLOOKUP($B37,'Rate card'!$A$4:$J236,7,FALSE) -> 50 | O37: =I37*N37 -> 17500
A38: 13 | B38: C45 | C38: =VLOOKUP($B38,'Rate card'!$A$4:$G236,2,FALSE) -> Civil | D38: =VLOOKUP($B38,'Rate card'!$A$4:$G236,3,FALSE) -> Vanity counter | E38: =VLOOKUP($B38,'Rate card'!$A$4:$G236,4,FALSE) -> Granite/Marble | F38: =VLOOKUP($B38,'Rate card'!$A$4:$G236,5,FALSE) -> Laying marble (18mm thk) of approved colour, shade and size on the platform as per drawing / flooring pattern, matching of grain, laid on a levelled, neat cement base with adhesive of approved make (laticrete) grouted of matching colour pigment to match the shade of stone and protection of floor to be taken into account.(cement concrete base taken into account in the civil works ) | G38: =VLOOKUP($B38,'Rate card'!$A$4:$G236,6,FALSE) -> Rft | H38: =VLOOKUP($B38,'Rate card'!$A$4:$J236,8,FALSE) -> 1500 | I38: 25 | J38: =H38*I38 -> 37500 | K38: Toilets | N38: =VLOOKUP($B38,'Rate card'!$A$4:$J236,7,FALSE) -> 1000 | O38: =I38*N38 -> 25000
I39: Total | J39: =SUM(J26:J38) -> 979240
A40: Plumbing
A41: 1 | B41: PL 2 | C41: Plumbing | D41: Bathroom Plumbing | E41: CP fitting work (1 WC+ 1Shower and divertor + 1 Basin + 1 Geyser) | F41: cp fiting and sanitary ware fixing in a bathroom (only fitting charges) | G41: per bathroom | H41: 45000 | I41: 5 | J41: =H41*I41 -> 225000 | K41: All Toilets, | N41: =VLOOKUP($B41,'Rate card'!$A$4:$J236,7,FALSE) -> 8000 | O41: =I41*N41 -> 40000
A42: 2 | B42: PL 3 | C42: =VLOOKUP($B42,'Rate card'!$A$4:$G236,2,FALSE) -> Plumbing | D42: =VLOOKUP($B42,'Rate card'!$A$4:$G236,3,FALSE) -> Kitchen Plumbing | E42: =VLOOKUP($B42,'Rate card'!$A$4:$G236,4,FALSE) -> Internal Concealed work (1 Basin + 1 Geyser) | F42: =VLOOKUP($B42,'Rate card'!$A$4:$G236,5,FALSE) -> all plumbing concealed wall and floor CPVC and UPVC pipes and chipping and replastering work | G42: =VLOOKUP($B42,'Rate card'!$A$4:$G236,6,FALSE) -> per kitchen | H42: 20000 | I42: 1 | J42: =H42*I42 -> 20000 | K42: Kitchen & Utility | N42: =VLOOKUP($B42,'Rate card'!$A$4:$J236,7,FALSE) -> 5500 | O42: =I42*N42 -> 5500
I43: Total | J43: =SUM(J41,J42) -> 245000
A44: Electrical
A45: 1 | B45: E 1 | C45: Electrical | D45: 5A Switch socket, Light points,AC point, Fan point, Circuit wiring, DB Dressing | E45: new 5A Switch & Socket, light points, 15A, AC point, fan point from DB on wall include the price for wire and conduits, chipping and replastering on wall is included | F45: NOTE - The rates include fixingof switch / socket in position, effecting proper connections testing and commissioning of lighting fixtures and fans including lamps, control gear, power factor improvement capacitor and all fixing accessories that may be required to check. | G45: All areas | H45: 350 | I45: 1673 | J45: =H45*I45 -> 585550 | K45: All areas | N45: =VLOOKUP($B45,'Rate card'!$A$4:$J236,7,FALSE) -> 625 | O45: =I45*N45 -> 1045625
I46: Total | J46: =SUM(J45) -> 585550
A47: Pop/Falsceiling
...

Sheet 14.03.25
A6: Date : | B6: 45730 | E6: Project Code :
A7: Client Name : | B7: Rahul Dhanawat | E7: Quotation Revision : | F7: 0
A8: Address : | B8: 10BKC | E8: Elemantra Contact Person : | F8: Payal- 93724 07848
P9: Add / modify | T9: Note
A10: Quotation Summary | G10: SR.NO | H10: Description | I10: Amount | P10: 1. Balcony
B11: Area in Sqft | D11: 1673 | G11: 1 | H11: Loose furniture | I11: =J211 -> 355000 | P11: 2. Utility tiles
A12: SR.NO | B12: Description | D12: Amount | G12: 2 | H12: Additional items | I12: =J225 -> 1651300 | P12: 3. Water outlets
A13: 1 | B13: Civil | D13: =J42 -> 566705 | H13: Total B | I13: =SUM(I11:I12) -> 2006300 | P13: 4. Kitchen flooring
A14: 2 | B14: Plumbing | D14: =J48 -> 125000 | G14: Total A+B | I14: =D21+I13 -> 8815486 | P14: 5. Smart lock at the entrace
A15: 3 | B15: Electrical | D15: =J51 -> 585550 | G15: GST 18% extra | P15: 6. Exhaust fans
A16: 4 | B16: POP | D16: =J59 -> 394840 | P16: 7. Rubber bidding
A17: 5 | B17: Carpentry | D17: =J152 -> 4148612.5 | P17: 8. Shaft closing
A18: 6 | B18: Painting | D18: =J158 -> 368478.5
A19: 7 | B19: Miscellenious | D19: =J163 -> 120000
A20: 8 | B20: Design Consultation Fees(10%) | D20: 500000
B21: Total A | D21: =SUM(D13:D20) -> 6809186
B22: Per Sqft Rate | D22: =(D21/D11) -> 4070.0454
A24: Sr.No | B24: Id | C24: Item Name | D24: Category | E24: Item Details | F24: Description | G24: UOM | H24: Elemantra Rates | I24: Quantity | J24: Amount | K24: Location | N24: Vendor Rate | O24: Amount
A25: Civil
A26: 1 | B26: D2 | C26: =VLOOKUP($B26,'Rate card'!$A$4:$G240,2,FALSE) -> Demolition | D26: =VLOOKUP($B26,'Rate card'!$A$4:$G240,3,FALSE) -> Brickwall - 6" | E26: =VLOOKUP($B26,'Rate card'!$A$4:$G240,4,FALSE) -> NA | F26: =VLOOKUP($B26,'Rate card'!$A$4:$G240,5,FALSE) -> Demolition | G26: =VLOOKUP($B26,'Rate card'!$A$4:$G240,6,FALSE) -> Sqft | H26: 500 | I26: =3*10+3*10 -> 60 | J26: =I26*H26 -> 30000 | K26: Kitchen & common toilet | O26: =VLOOKUP($B26,'Rate card'!$A$4:$J240,7,FALSE) -> 20
A27: 2 | C27: Civil | D27: Brickwall - 4" | E27: =E26 -> NA | F27: Providing and laying 4" (100 MM) brick partition wall with good quality bricks well burnt 1st class in cement mortar 1:4 (1 cement : 4 coarse sand) including providing 2 nos of 6mm dia MS round bars at every IV course including scaffolding, curing, raking out joints etc. complete. | G27: =#REF! -> #REF! | H27: 150 | I27: =3*10+3*10 -> 60 | J27: =I27*H27 -> 9000 | K27: Kitchen & common toilet
A28: 3 | C28: Civil | D28: Plaster | E28: =E26 -> NA | F28: Providing and laying 12-25 mm thick cement plaster of mis 1 : 4 (1 cement : 4 sand with 50% coarse sand & 50% fine sand) to all type of RCC / brick surface in line, level and plumb including providing wiremesh at all junctions of walls and ceilings etc. complete. | G28: Sqft | H28: 120 | I28: =I27 -> 60 | J28: =I28*H28 -> 7200 | K28: Kitchen & common toilet
A29: 4 | B29: C23 | C29: =VLOOKUP($B29,'Rate card'!$A$4:$G240,2,FALSE) -> Civil | D29: =VLOOKUP($B29,'Rate card'!$A$4:$G240,3,FALSE) -> Kitchen platform | E29: =VLOOKUP($B29,'Rate card'!$A$4:$G240,4,FALSE) -> Fully Modular Kitchen - Granite/Marble | F29: =VLOOKUP($B29,'Rate card'!$A$4:$G240,5,FALSE) -> Laying marble (18mm thk) of approved colour, shade and size on the platform as per drawing / flooring pattern, matching of grain, laid on a levelled, neat cement base with adhesive of approved make (laticrete) grouted of matching colour pigment to match the shade of stone and protection of floor to be taken into account.(cement concrete base taken into account in the civil works ) | G29: =VLOOKUP($B29,'Rate card'!$A$4:$G240,6,FALSE) -> Sqft | H29: 500 | I29: =18.5*2 -> 37 | J29: =I29*H29 -> 18500 | K29: Kitchen | O29: =VLOOKUP($B29,'Rate card'!$A$4:$J240,7,FALSE) -> 150
A30: 5 | C30: Civil | D30: Plaster | E30: =E28 -> NA | F30: Providing and laying 12-25 mm thick cement plaster of mis 1 : 4 (1 cement : 4 sand with 50% coarse sand & 50% fine sand) to all type of RCC / brick surface in line, level and plumb including providing wiremesh at all junctions of walls and ceilings etc. complete. | G30: Sqft | H30: 120 | I30: =I31 -> 192.5 | J30: =I30*H30 -> 23100 | K30: Kitchen wall
A31: 6 | C31: Civil | D31: Kitchen wall tiles | E31: Upto( 4' x 2' ) tiles laying | F31: Laying of Wall tiles of approved colour and size as per drawing, over 20 mm thick cement mortar 1 : 4 ( 1 cement : 4 coarse sand ) and jointed with white cement slurry admixed with matching pigment to match the shade of tile & Grouting and spacer to be included. | G31: Sqft | H31: 140 | I31: =11.25*7+1.5*7+12*7+2.75*7 -> 192.5 | J31: =I31*H31 -> 26950 | K31: Kitchen
A32: 7 | B32: C27 | C32: =VLOOKUP($B32,'Rate card'!$A$4:$G240,2,FALSE) -> Civil | D32: =VLOOKUP($B32,'Rate card'!$A$4:$G240,3,FALSE) -> Brickbat | E32: =VLOOKUP($B32,'Rate card'!$A$4:$G240,4,FALSE) | F32: =VLOOKUP($B32,'Rate card'!$A$4:$G240,5,FALSE) -> Providing & laying brickbat coba (6") with PCC | G32: =VLOOKUP($B32,'Rate card'!$A$4:$G240,6,FALSE) -> Sqft | H32: =VLOOKUP($B32,'Rate card'!$A$4:$J240,8,FALSE) -> 200 | I32: =55+40+40+57 -> 192 | J32: =H32*I32 -> 38400 | K32: Toilets | N32: =VLOOKUP($B32,'Rate card'!$A$4:$J240,7,FALSE) -> 150 | O32: =I32*N32 -> 28800
A33: 8 | B33: C30 | C33: =VLOOKUP($B33,'Rate card'!$A$4:$G240,2,FALSE) -> Civil | D33: =VLOOKUP($B33,'Rate card'!$A$4:$G240,3,FALSE) -> Waterproofing | E33: Floor & walls | F33: =VLOOKUP($B33,'Rate card'!$A$4:$G240,5,FALSE) -> Waterproofing with 2 coats | G33: =VLOOKUP($B33,'Rate card'!$A$4:$G240,6,FALSE) -> Sqft | H33: =VLOOKUP($B33,'Rate card'!$A$4:$J240,8,FALSE) -> 80 | I33: 350 | J33: =H33*I33 -> 28000 | K33: Toilets | N33: =VLOOKUP($B33,'Rate card'!$A$4:$J240,7,FALSE) -> 50 | O33: =I33*N33 -> 17500
A34: 9 | C34: Civil | D34: Plaster | E34: =E30 -> NA | F34: Providing and laying 12-25 mm thick cement plaster of mis 1 : 4 (1 cement : 4 sand with 50% coarse sand & 50% fine sand) to all type of RCC / brick surface in line, level and plumb including providing wiremesh at all junctions of walls and ceilings etc. complete. | G34: Sqft | H34: 120 | I34: =272+234+234+275 -> 1015 | J34: =I34*H34 -> 121800 | K34: Bathroom walls
A35: 10 | C35: Civil | D35: Bathroom floor & wall tiles | E35: Upto( 4' x 2' ) tiles laying | F35: Laying of Wall tiles of approved colour and size as per drawing, over 20 mm thick cement mortar 1 : 4 ( 1 cement : 4 coarse sand ) and jointed with white cement slurry admixed with matching pigment to match the shade of tile & Grouting and spacer to be included. | G35: Sqft | H35: 140 | I35: =55+272+40+234+40+234+57+275 -> 1207 | J35: =I35*H35 -> 168980 | K35: Toilets
A36: 11 | B36: C23 | C36: =VLOOKUP($B36,'Rate card'!$A$4:$G240,2,FALSE) -> Civil | D36: Utility platfrom | E36: =VLOOKUP($B36,'Rate card'!$A$4:$G240,4,FALSE) -> Fully Modular Kitchen - Granite/Marble | F36: =VLOOKUP($B36,'Rate card'!$A$4:$G240,5,FALSE) -> Laying marble (18mm thk) of approved colour, shade and size on the platform as per drawing / flooring pattern, matching of grain, laid on a levelled, neat cement base with adhesive of approved make (laticrete) grouted of matching colour pigment to match the shade of stone and protection of floor to be taken into account.(cement concrete base taken into account in the civil works ) | G36: =VLOOKUP($B36,'Rate card'!$A$4:$G240,6,FALSE) -> Sqft | H36: 500 | I36: 10 | J36: =I36*H36 -> 5000 | K36: utility | O36: =VLOOKUP($B36,'Rate card'!$A$4:$J240,7,FALSE) -> 150
A37: 12 | B37: C15 | C37: =VLOOKUP($B37,'Rate card'!$A$4:$G240,2,FALSE) -> Civil | D37: =VLOOKUP($B37,'Rate card'!$A$4:$G240,3,FALSE) -> Granite frames | E37: =VLOOKUP($B37,'Rate card'!$A$4:$G240,4,FALSE) -> Single patti | F37: =VLOOKUP($B37,'Rate card'!$A$4:$G240,5,FALSE) -> Granite Frame – up to 6 Inches width {Including Bevelling+ Cutting+ Polishing}. Excludes Granite cost | G37: =VLOOKUP($B37,'Rate card'!$A$4:$G240,6,FALSE) -> Rft | H37: =VLOOKUP($B37,'Rate card'!$A$4:$J240,8,FALSE) -> 130 | I37: =20*4 -> 80 | J37: =H37*I37 -> 10400 | K37: kitchen & Toilets | N37: =VLOOKUP($B37,'Rate card'!$A$4:$J240,7,FALSE) -> 80 | O37: =I37*N37 -> 6400
A38: 13 | B38: C45 | C38: =VLOOKUP($B38,'Rate card'!$A$4:$G240,2,FALSE) -> Civil | D38: =VLOOKUP($B38,'Rate card'!$A$4:$G240,3,FALSE) -> Vanity counter | E38: =VLOOKUP($B38,'Rate card'!$A$4:$G240,4,FALSE) -> Granite/Marble | F38: =VLOOKUP($B38,'Rate card'!$A$4:$G240,5,FALSE) -> Laying marble (18mm thk) of approved colour, shade and size on the platform as per drawing / flooring pattern, matching of grain, laid on a levelled, neat cement base with adhesive of approved make (laticrete) grouted of matching colour pigment to match the shade of stone and protection of floor to be taken into account.(cement concrete base taken into account in the civil works ) | G38: =VLOOKUP($B38,'Rate card'!$A$4:$G240,6,FALSE) -> Rft | H38: =VLOOKUP($B38,'Rate card'!$A$4:$J240,8,FALSE) -> 1500 | I38: 22 | J38: =H38*I38 -> 33000 | K38: Toilets | N38: =VLOOKUP($B38,'Rate card'!$A$4:$J240,7,FALSE) -> 1000 | O38: =I38*N38 -> 22000
A39: 14 | C39: Tiles behind Wardrobe | G39: sqft | H39: 50 | I39: =I92+I95+I107+I120+I131 -> 327.5 | J39: =(H39*I39) -> 16375 | K39: Behind wardrobe
A40: 15
A41: 13 | B41: C45 | C41: =VLOOKUP($B41,'Rate card'!$A$4:$G240,2,FALSE) -> Civil | D41: Ledge | E41: =VLOOKUP($B41,'Rate card'!$A$4:$G240,4,FALSE) -> Granite/Marble | F41: =VLOOKUP($B41,'Rate card'!$A$4:$G240,5,FALSE) -> Laying marble (18mm thk) of approved colour, shade and size on the platform as per drawing / flooring pattern, matching of grain, laid on a levelled, neat cement base with adhesive of approved make (laticrete) grouted of matching colour pigment to match the shade of stone and protection of floor to be taken into account.(cement concrete base taken into account in the civil works ) | G41: =VLOOKUP($B41,'Rate card'!$A$4:$G240,6,FALSE) -> Rft | H41: =VLOOKUP($B41,'Rate card'!$A$4:$J240,8,FALSE) -> 1500 | I41: 20 | J41: =H41*I41 -> 30000 | K41: Toilets | N41: =VLOOKUP($B41,'Rate card'!$A$4:$J240,7,FALSE) -> 1000 | O41: =I41*N41 -> 20000
I42: Total | J42: =SUM(J26:J41) -> 566705
A43: Plumbing
A44: 1 | B44: PL 2 | C44: Plumbing | D44: Bathroom Plumbing | E44: CP fitting work 1 Basin +cp fittings+Ceiling shower | F44: cp fiting and sanitary ware fixing in a bathroom | G44: per bathroom | H44: 35000 | I44: 1 | J44: =H44*I44 -> 35000 | K44: Samar's toilet | N44: =VLOOKUP($B44,'Rate card'!$A$4:$J240,7,FALSE) -> 8000 | O44: =I44*N44 -> 8000
A45: 2 | B45: PL 2 | C45: Plumbing | D45: Bathroom Plumbing | E45: Ceiling shower+body jets+c.p fittings | F45: cp fiting and sanitary ware fixing in a bathroom | G45: per bathroom | H45: 40000 | I45: 1 | J45: =H45*I45 -> 40000 | K45: Master & Ranbeer | N45: =VLOOKUP($B45,'Rate card'!$A$4:$J240,7,FALSE) -> 8000 | O45: =I45*N45 -> 8000
A46: 3 | B46: PL 2 | C46: Plumbing | D46: Bathroom Plumbing | E46: CP fitting work 1 Basin +cp fittings+Ceiling shower | F46: cp fiting and sanitary ware fixing in a bathroom | G46: per bathroom | H46: 25000 | I46: 1 | J46: =H46*I46 -> 25000 | K46: Mother's toilet | N46: =VLOOKUP($B46,'Rate card'!$A$4:$J240,7,FALSE) -> 8000 | O46: =I46*N46 -> 8000
...

Sheet Amruta - recheck
A6: Date : | B6: 45730 | E6: Project Code :
A7: Client Name : | B7: Rahul Dhanawat | E7: Quotation Revision : | F7: 0
A8: Address : | B8: 10BKC | E8: Elemantra Contact Person : | F8: Payal- 93724 07848
A10: Quotation Summary | E10: SR.NO | F10: Description | G10: Amount
B11: Area in Sqft | D11: 1673 | E11: 1 | F11: Loose furniture | G11: =J247 -> 460000
A12: SR.NO | B12: Description | D12: Amount | E12: 2 | F12: Additional items | G12: =K261
A13: 1 | B13: Civil | D13: =M42 -> 778690 | F13: Total B | G13: =SUM(G11:G12) -> 460000
A14: 2 | B14: Plumbing | D14: =M48 -> 135000 | E14: Total A+B | G14: =D22+G11+G12 -> 9865831
A15: 3 | B15: Electrical | D15: =M51 -> 585550 | E15: GST 18% extra
A16: 4 | B16: POP | D16: =M58 -> 420000
A17: 5 | B17: Carpentry | D17: =M153 -> 5150250
A18: 6 | B18: Painting | D18: =M159 -> 1048478.5
A19: 7 | B19: Miscellenious | D19: =J164 -> 190000
B20: NON BOQ | D20: =J209 -> 597862.5
A21: 8 | B21: Design Consultation Fees(10%) | D21: 500000
B22: Total A | D22: =SUM(D13:D21) -> 9405831
B23: Per Sqft Rate | D23: =(D22/D11) -> 5622.1345
A25: Sr.No | B25: Id | C25: Item Name | D25: Category | E25: Item Details | F25: Description | G25: UOM | H25: Elemantra Rates | I25: Quantity 14.03.2025 | J25: Amount | K25: Area | L25: Difference Amount | M25: Amount | N25: Location | O25: Remark
A26: Civil
A27: 1 | C27: Demolition | D27: walls | E27: NA | F27: Demolition | G27: sq.ft | H27: 50 | I27: =H27-(H27*16.622%) -> 41.689 | J27: 40 | K27: =3+3+7*9+100 -> 169 | L27: Entire kitchen this includes below platform as well since wwe are changing verticles it will get damage . | M27: =K27*H27 -> 8450 | N27: servent ,samar & master bathroom door shifting | O27: keeping 100 sq.ft extra
A28: 2 | C28: civil | D28: walls | E28: NA | F28: Making | G28: sq.ft | H28: 200 | I28: - | J28: - | K28: =6*9 -> 54 | L28: Kitchen Window &door frame | M28: =K28*H28 -> 10800 | N28: samar & master bathroom wall sfifting
A29: 3 | C29: civil | D29: kitchen platform | E29: NA | F29: includes marble verticals, base marble, moulding , cutting etc , also includes floor bedding with marble | G29: rft | H29: 3000 | K29: 25 | M29: =K29*H29 -> 75000 | N29: kitchen platform
A30: 4 | C30: civil | D30: utility platform | E30: NA | F30: includes marble verticals, base marble, moulding , cutting etc , also includes floor bedding with marble | G30: sq.ft | H30: 3000 | K30: 9 | M30: =K30*H30 -> 27000 | N30: utility platform
A31: 5 | C31: civil | D31: Bathroom Tile | E31: 4x2 tile | F31: Laying of Wall tiles of approved colour and size as per drawing, over 20 mm thick cement mortar 1 : 4 ( 1 cement : 4 coarse sand ) and jointed with white cement slurry admixed with matching pigment to match the shade of tile & Grouting and spacer to be included. | G31: sq.ft | H31: 150 | K31: 1050 | M31: =K31*H31 -> 157500 | N31: 4 Bathroom Tile
A32: 6 | C32: civil | D32: Plaster | F32: Providing and laying 12-25 mm thick cement plaster of mis 1 : 4 (1 cement : 4 sand with 50% coarse sand & 50% fine sand) to all type of RCC / brick surface in line, level and plumb including providing wiremesh at all junctions of walls and ceilings etc. complete. | G32: sq.ft | H32: 120 | K32: 1600 | M32: =K32*H32 -> 192000 | N32: 4 Bathroom Tile
A33: 7 | C33: civil | D33: bathroom window frame | E33: single patti | F33: Granite Frame – up to 6 Inches width {Including Bevelling+ Cutting+ Polishing}. Excludes Granite cost | G33: sq.ft | H33: 130 | K33: =10*4+18+18+12+50 -> 138 | M33: =K33*H33 -> 17940 | N33: 4 bathroom window and 1 kitchen window and 1 show unit window
A34: 8 | C34: civil | D34: brickbat | F34: =VLOOKUP($B34,'Rate card'!$A$4:$G279,5,FALSE) -> 0 | G34: sq.ft | H34: 200 | K34: =40*4 -> 160 | M34: =K34*H34 -> 32000 | N34: 4 bathroom floor
A35: 9 | C35: civil | D35: waterproffing | E35: 2 cote | G35: sq.ft | H35: 250 | K35: =K34 -> 160 | M35: =K35*H35 -> 40000 | N35: 4 bathroom floor
A36: 10 | C36: civil | D36: Bathroom floor tile | F36: Laying of Wall tiles of approved colour and size as per drawing, over 20 mm thick cement mortar 1 : 4 ( 1 cement : 4 coarse sand ) and jointed with white cement slurry admixed with matching pigment to match the shade of tile & Grouting and spacer to be included. | G36: sq.ft | H36: 150 | K36: =K35 -> 160 | M36: =K36*H36 -> 24000 | N36: 4 bathroom floor
A37: 11 | C37: civil | D37: vanity counter | G37: ls | H37: 8000 | K37: 4 | M37: =K37*H37 -> 32000
A38: 12 | C38: civil | D38: ledge | G38: la | H38: 5000 | K38: 4 | M38: =K38*H38 -> 20000
A39: 13 | M39: =K39*H39 -> 0
A40: 14 | C40: civil | D40: plain tile | G40: sq.ft | H40: 120 | K40: 350 | M40: =K40*H40 -> 42000 | N40: tile behid utility and below platform
A41: 15 | C41: civil | D41: marble wardrobe in utility area | G41: sq.ft | H41: 400 | K41: 250 | M41: =K41*H41 -> 100000 | N41: marble wardrobe in utility area | O41: shutters are not included
K42: Total | M42: =SUM(M27:M41) -> 778690
A43: Plumbing
A44: 1 | B44: PL 2 | C44: Plumbing | D44: Bathroom Plumbing | E44: CP fitting work 1 Basin +cp fittings+Ceiling shower | F44: cp fiting and sanitary ware fixing in a bathroom | G44: per bathroom | H44: 35000 | I44: 1 | J44: =H44*I44 -> 35000 | K44: 1 | L44: =K44-J44 -> -34999 | M44: =K44*H44 -> 35000 | N44: Samar's toilet
A45: 2 | B45: PL 2 | C45: Plumbing | D45: Bathroom Plumbing | E45: Ceiling shower+body jets+c.p fittings | F45: cp fiting and sanitary ware fixing in a bathroom | G45: per bathroom | H45: 45000 | I45: 1 | J45: =H45*I45 -> 45000 | K45: 1 | L45: =K45-J45 -> -44999 | M45: =K45*H45 -> 45000 | N45: Master & Ranbeer
A46: 3 | B46: PL 2 | C46: Plumbing | D46: Bathroom Plumbing | E46: CP fitting work 1 Basin +cp fittings+Ceiling shower | F46: cp fiting and sanitary ware fixing in a bathroom | G46: per bathroom | H46: 35000 | I46: 1 | J46: =J44 -> 35000 | K46: 1 | L46: =K46-J46 -> -34999 | M46: =K46*H46 -> 35000 | N46: Mother's toilet
A47: 4 | B47: PL 3 | C47: =VLOOKUP($B47,'Rate card'!$A$4:$G279,2,FALSE) -> Plumbing | D47: =VLOOKUP($B47,'Rate card'!$A$4:$G279,3,FALSE) -> Kitchen Plumbing | E47: 3 sink+dishwahser+washing machine | F47: =VLOOKUP($B47,'Rate card'!$A$4:$G279,5,FALSE) -> all plumbing concealed wall and floor CPVC and UPVC pipes and chipping and replastering work | G47: =VLOOKUP($B47,'Rate card'!$A$4:$G279,6,FALSE) -> per kitchen | H47: 20000 | I47: 1 | J47: =H47*I47 -> 20000 | K47: 1 | L47: =K47-J47 -> -19999 | M47: =K47*H47 -> 20000 | N47: Kitchen & Utility
...

Sheet 18.06.25
A6: Date : | B6: 45730 | E6: Project Code :
A7: Client Name : | B7: Rahul Dhanawat | E7: Quotation Revision : | F7: 0
A8: Address : | B8: 10BKC | E8: Elemantra Contact Person : | F8: Payal- 93724 07848
S9: Add / modify | W9: Note
A10: Quotation Summary | G10: SR.NO | H10: Description | I10: Amount | S10: 1. Balcony
B11: Area in Sqft | D11: 1673 | G11: 1 | H11: Loose furniture | I11: =J248 -> 460000 | S11: 2. Utility tiles
A12: SR.NO | B12: Description | D12: Amount | G12: 2 | H12: Additional items | I12: =L262 -> 2810400 | S12: 3. Water outlets
A13: 1 | B13: Civil | D13: =L43 -> 845895 | H13: Total B | I13: =SUM(I11:I12) -> 3270400 | S13: 4. Kitchen flooring
A14: 2 | B14: Plumbing | D14: =L49 -> 185000 | G14: Total A+B | I14: =D22+I11+I12 -> 12941066 | S14: 5. Smart lock at the entrace
A15: 3 | B15: Electrical | D15: =L52 -> 585550 | G15: GST 18% extra | S15: 6. Exhaust fans
A16: 4 | B16: POP | D16: =L60 -> 394840 | S16: 7. Rubber bidding
A17: 5 | B17: Carpentry | D17: =L153 -> 5298040 | S17: 8. Shaft closing
A18: 6 | B18: Painting | D18: =L160 -> 1073478.5
A19: 7 | B19: Miscellenious | D19: =J165 -> 190000
B20: NON BOQ | D20: =J210 -> 597862.5
A21: 8 | B21: Design Consultation Fees(10%) | D21: 500000
B22: Total A | D22: =SUM(D13:D21) -> 9670666
B23: Per Sqft Rate | D23: =(D22/D11) -> 5780.434
A25: Sr.No | B25: Id | C25: Item Name | D25: Category | E25: Item Details | F25: Description | G25: UOM | H25: Elemantra Rates | I25: Quantity 14.03.2025 | J25: Amount | K25: Quantity 18.06.2025 | L25: Amount 18.06.2025 | M25: Difference Amount | N25: Location | O25: Remark | Q25: Vendor Rate | R25: Amount
A26: Civil
A27: 1 | B27: D2 | C27: =VLOOKUP($B27,'Rate card'!$A$4:$G280,2,FALSE) -> Demolition | D27: =VLOOKUP($B27,'Rate card'!$A$4:$G280,3,FALSE) -> Brickwall - 6" | E27: =VLOOKUP($B27,'Rate card'!$A$4:$G280,4,FALSE) -> NA | F27: =VLOOKUP($B27,'Rate card'!$A$4:$G280,5,FALSE) -> Demolition | G27: =VLOOKUP($B27,'Rate card'!$A$4:$G280,6,FALSE) -> Sqft | H27: 500 | I27: =3*10+3*10 -> 60 | J27: =I27*H27 -> 30000 | K27: =1.5*10.5+2.25*2.6+3*10.25+2.75*10.25+2.75*8+3*10.25 -> 133.2875 | L27: =K27*H27 -> 66643.75 | M27: =L27-J27 -> 36643.75 | N27: Kitchen & common toilet+Samar toilet+Master bed room | O27: Qty ⬆️ | R27: =VLOOKUP($B27,'Rate card'!$A$4:$J280,7,FALSE) -> 20 | S27: =L27/$D$22 -> 0.0068913299
A28: 2 | C28: Civil | D28: Brickwall - 4" | E28: =E27 -> NA | F28: Providing and laying 4" (100 MM) brick partition wall with good quality bricks well burnt 1st class in cement mortar 1:4 (1 cement : 4 coarse sand) including providing 2 nos of 6mm dia MS round bars at every IV course including scaffolding, curing, raking out joints etc. complete. | G28: =G27 -> Sqft | H28: 150 | I28: =3*10+3*10 -> 60 | J28: =I28*H28 -> 9000 | K28: =1.5*10.25+3*10.25+2.75*8+3*10.25 -> 98.875 | L28: =K28*H28 -> 14831.25 | M28: =L28-J28 -> 5831.25 | N28: Kitchen,samar toilet,master toilet | O28: Qty ⬆️ | S28: =L28/$D$22 -> 0.0015336327
A29: 3 | C29: Civil | D29: Plaster | E29: =E27 -> NA | F29: Providing and laying 12-25 mm thick cement plaster of mis 1 : 4 (1 cement : 4 sand with 50% coarse sand & 50% fine sand) to all type of RCC / brick surface in line, level and plumb including providing wiremesh at all junctions of walls and ceilings etc. complete. | G29: Sqft | H29: 120 | I29: =I28 -> 60 | J29: =I29*H29 -> 7200 | K29: 200 | L29: =K29*H29 -> 24000 | M29: =L29-J29 -> 16800 | N29: Kitchen,samar toilet,master toilet | O29: Qty ⬆️ | S29: =L29/$D$22 -> 0.0024817319
A30: 4 | B30: C23 | C30: =VLOOKUP($B30,'Rate card'!$A$4:$G280,2,FALSE) -> Civil | D30: =VLOOKUP($B30,'Rate card'!$A$4:$G280,3,FALSE) -> Kitchen platform | E30: =VLOOKUP($B30,'Rate card'!$A$4:$G280,4,FALSE) -> Fully Modular Kitchen - Granite/Marble | F30: =VLOOKUP($B30,'Rate card'!$A$4:$G280,5,FALSE) -> Laying marble (18mm thk) of approved colour, shade and size on the platform as per drawing / flooring pattern, matching of grain, laid on a levelled, neat cement base with adhesive of approved make (laticrete) grouted of matching colour pigment to match the shade of stone and protection of floor to be taken into account.(cement concrete base taken into account in the civil works ) | G30: =VLOOKUP($B30,'Rate card'!$A$4:$G280,6,FALSE) -> Sqft | H30: 3000 | I30: =18.5*2 -> 37 | J30: =I30*H30 -> 111000 | K30: 52 | L30: =K30*H30 -> 156000 | M30: =L30-J30 -> 45000 | N30: Kitchen | O30: Qty ⬆️ | R30: =VLOOKUP($B30,'Rate card'!$A$4:$J280,7,FALSE) -> 150 | S30: =L30/$D$22 -> 0.016131257
A31: 5 | C31: Civil | D31: Plaster | E31: =E29 -> NA | F31: Providing and laying 12-25 mm thick cement plaster of mis 1 : 4 (1 cement : 4 sand with 50% coarse sand & 50% fine sand) to all type of RCC / brick surface in line, level and plumb including providing wiremesh at all junctions of walls and ceilings etc. complete. | G31: Sqft | H31: 120 | I31: =I32 -> 192.5 | J31: =I31*H31 -> 23100 | K31: 185 | L31: =K31*H31 -> 22200 | M31: =L31-J31 -> -900 | N31: Kitchen wall | O31: Qty ⬇️ | S31: =L31/$D$22 -> 0.002295602
